<?xml version='1.0'?>
<sdf version='1.5'>
    <model name="BLUE">
        <static>false</static>

        <link name='Base'>
            <pose>.40 0 .445 0 0 0</pose>
            <collision name='collision'>
                <geometry>
                    <box>
                        <size>1.300 .800 .030</size>
                    </box>
                </geometry>
            </collision>
            <visual name='visual'>
                <geometry>
                    <box>
                        <size>1.300 .800 .030</size>
                    </box>
		</geometry>
		<material>
			<ambient>0 0 1 1</ambient>
			<diffuse>0 0 1 1</diffuse>
			<specular>0 0 0 0</specular>
			<emissive>0 0 0 0</emissive>
		</material>
            </visual>
        </link>
        
        <link name='Pole'>
            <pose>.50 0 .760 0 0 0</pose>
            <collision name='collision'>
                <geometry>
                    <cylinder>
                        <radius>.030</radius>
                        <length>.600</length>
                    </cylinder>
                </geometry>
            </collision>
            <visual name='visual'>
                <geometry>
                    <cylinder>
                        <radius>.030</radius>
                        <length>.600</length>
                    </cylinder>
                </geometry>
		<material>
			<ambient>.5 .5 .5 1</ambient>
			<diffuse>.5 .5 .5 1</diffuse>
			<specular>0 0 0 0</specular>
			<emissive>0 0 0 0</emissive>
		</material>
            </visual>
        </link>

        <link name='Velodyne'>
            <pose>.50 0 1.090 0 0 0</pose>
            <collision name='collision'>
                <geometry>
                    <cylinder>
                        <radius>.070</radius>
                        <length>.1260</length>
                    </cylinder>
                </geometry>
            </collision>
            <visual name='visual'>
                <geometry>
                    <cylinder>
                        <radius>.070</radius>
                        <length>.1260</length>
                    </cylinder>
                </geometry>
		<material>
			<ambient>0 1 0 1</ambient>
			<diffuse>0 1 0 1</diffuse>
			<specular>0 0 0 0</specular>
			<emissive>0 0 0 0</emissive>
		</material>
            </visual>
        </link>

        <link name='GNSSRover'>
            <pose>0 0 .4675 0 0 0</pose>
            <collision name='collision'>
                <geometry>
		<material>
			<ambient>0 0 0 1</ambient>
			<diffuse>0 0 0 1</diffuse>
			<specular>0 0 0 0</specular>
			<emissive>0 0 0 0</emissive>
		</material>
                    <box>
                        <size>.050 .045 .015</size>
                    </box>
                </geometry>
            </collision>
            <visual name='visual'>
                <geometry>
                    <box>
                        <size>.050 .045 .015</size>
                    </box>
                </geometry>
            </visual>
        </link>

        <link name='IMU'>
            <pose>0 0 .42675 0 0 0</pose>
            <collision name='collision'>
                <geometry>
                    <box>
                        <size>.0270 .0260 .0065</size>
                    </box>
                </geometry>
            </collision>
            <visual name='visual'>
                <geometry>
                    <box>
                        <size>.0270 .0260 .0065</size>
                    </box>
                </geometry>
		<material>
			<ambient>1 0 0 1</ambient>
			<diffuse>1 0 0 1</diffuse>
			<specular>0 0 0 0</specular>
			<emissive>0 0 0 0</emissive>
		</material>
            </visual>
        </link>

        <link name="LFWheel">
            <pose>1.06 -.3370 .0775 1.57080 1.57080 0</pose>
            <collision name="collision">
                <geometry>
                    <cylinder>
                        <radius>.1550</radius>
                        <length>.1260</length>
                    </cylinder>
                </geometry>
            </collision>
            <visual name="visual">
                <geometry>
                    <cylinder>
                        <radius>.1550</radius>
                        <length>.1260</length>
                    </cylinder>
                </geometry>
		<material>
			<ambient>0 0 0 1</ambient>
			<diffuse>0 0 0 1</diffuse>
			<specular>0 0 0 0</specular>
			<emissive>0 0 0 0</emissive>
		</material>
            </visual>
        </link>
        
        <link name="RFWheel">
            <pose>1.06 .3370 .0775 1.57080 1.57080 0</pose>
            <collision name="collision">
                <geometry>
                    <cylinder>
                        <radius>.1550</radius>
                        <length>.1260</length>
                    </cylinder>
                </geometry>
            </collision>
            <visual name="visual">
                <geometry>
                    <cylinder>
                        <radius>.1550</radius>
                        <length>.1260</length>
                    </cylinder>
                </geometry>
		<material>
			<ambient>0 0 0 1</ambient>
			<diffuse>0 0 0 1</diffuse>
			<specular>0 0 0 0</specular>
			<emissive>0 0 0 0</emissive>
		</material>
            </visual>
        </link>

        <link name="LRWheel">
            <pose>0 -.3184 .09875 1.57080 1.57080 0</pose>
            <collision name="collision">
                <geometry>
                    <cylinder>
                        <radius>.1975</radius>
                        <length>.1632</length>
                    </cylinder>
                </geometry>
            </collision>
            <visual name="visual">
                <geometry>
                    <cylinder>
                        <radius>.1975</radius>
                        <length>.1632</length>
                    </cylinder>
                </geometry>
		<material>
			<ambient>0 0 0 1</ambient>
			<diffuse>0 0 0 1</diffuse>
			<specular>0 0 0 0</specular>
			<emissive>0 0 0 0</emissive>
		</material>
            </visual>
        </link>

        <link name="RRWheel">
            <pose>0 .3184 .09875 1.57080 1.57080 0</pose>
            <collision name="collision">
                <geometry>
                    <cylinder>
                        <radius>.1975</radius>
                        <length>.1632</length>
                    </cylinder>
                </geometry>
            </collision>
            <visual name="visual">
                <geometry>
                    <cylinder>
                        <radius>.1975</radius>
                        <length>.1632</length>
                    </cylinder>
                </geometry>
		<material>
			<ambient>0 0 0 1</ambient>
			<diffuse>0 0 0 1</diffuse>
			<specular>0 0 0 0</specular>
			<emissive>0 0 0 0</emissive>
		</material>
            </visual>
        </link>

        <joint type="fixed" name="BasePole">
            <pose>.40 0 .770 0 0 0</pose>
            <child>Pole</child>
            <parent>Base</parent>
            <axis>
                <xyz>0 0 0</xyz>
            </axis>
        </joint>

        <joint type="fixed" name="PoleVelodyne">
            <pose>.40 0 1.100 0 0 0</pose>
            <child>Velodyne</child>
            <parent>Base</parent>
            <axis>
                <xyz>0 0 0</xyz>
            </axis>
        </joint>

        <joint type="fixed" name="BaseGNSSRover">
            <pose>0 0 .0.4675 0 0 0</pose>
            <child>GNSSRover</child>
            <parent>Base</parent>
            <axis>
                <xyz>0 0 0</xyz>
            </axis>
        </joint>

        <joint type="fixed" name="BaseIMU">
            <pose>0 0 .42675 0 0 0</pose>
            <child>IMU</child>
            <parent>Base</parent>
            <axis>
                <xyz>0 0 0</xyz>
            </axis>
        </joint>

        <joint type="revolute" name="LeftFrontWheel">
            <pose>1.06 -.3370 .0775 1.57080 1.57080 0</pose>
            <child>LFWheel</child>
            <parent>Base</parent>
            <axis>
                <xyz>0 1 0</xyz>
            </axis>
        </joint>

        <joint type="revolute" name="RightFrontWheel">
            <pose>1.06 .3370 .0775 1.57080 1.57080 0</pose>
            <child>RFWheel</child>
            <parent>Base</parent>
            <axis>
                <xyz>0 1 0</xyz>
            </axis>
        </joint>

        <joint type="revolute" name="LeftRearWheel">
            <pose>0 -.3184 .09875 1.57080 1.57080 0</pose>
            <child>LRWheel</child>
            <parent>Base</parent>
            <axis>
                <xyz>0 1 0</xyz>
            </axis>
        </joint>

        <joint type="revolute" name="RightRearWheel">
            <pose>0 .3184 .09875 1.57080 1.57080 0</pose>
            <child>RRWheel</child>
            <parent>Base</parent>
            <axis>
                <xyz>0 1 0</xyz>
            </axis>
        </joint>

    </model>
</sdf>
